Workbook
Name _DSA: #REF!
Name _DSA: #REF!
Name _DSA: #REF!
Name ASDS: #REF!
Name ASDS: #REF!
Name ASDS: #REF!
Name CFGauth: #REF!
Name CFGauth: #REF!
Name CFGauth: #REF!
Name cfgAuthPwd: #REF!
Name cfgAuthPwd: #REF!
Name cfgAuthPwd: #REF!
Name cfgAuthUser: #REF!
Name cfgAuthUser: #REF!
Name cfgAuthUser: #REF!
Name cfgBaseLanguage: #REF!
Name cfgBaseLanguage: #REF!
Name cfgBaseLanguage: #REF!
Name cfgBatchSize: #REF!
Name cfgBatchSize: #REF!
Name cfgBatchSize: #REF!
Name cfgConnectTimeout: #REF!
Name cfgConnectTimeout: #REF!
Name cfgConnectTimeout: #REF!
Name cfgContinueSync: #REF!
Name cfgContinueSync: #REF!
Name cfgContinueSync: #REF!
Name cfgDateFormat: #REF!
Name cfgDateFormat: #REF!
Name cfgDateFormat: #REF!
Name cfgDateTimeFormat: #REF!
Name cfgDateTimeFormat: #REF!
Name cfgDateTimeFormat: #REF!
Name cfgDisplaySummary: #REF!
Name cfgDisplaySummary: #REF!
Name cfgDisplaySummary: #REF!
Name cfgEnableAuth: #REF!
Name cfgEnableAuth: #REF!
Name cfgEnableAuth: #REF!
Name cfgLogEnabled: #REF!
Name cfgLogEnabled: #REF!
Name cfgLogEnabled: #REF!
Name cfgLogFileName: #REF!
Name cfgLogFileName: #REF!
Name cfgLogFileName: #REF!
Name cfgLogLevel: #REF!
Name cfgLogLevel: #REF!
Name cfgLogLevel: #REF!
Name cfgMaxCount: #REF!
Name cfgMaxCount: #REF!
Name cfgMaxCount: #REF!
Name cfgMxUrl: #REF!
Name cfgMxUrl: #REF!
Name cfgMxUrl: #REF!
Name cfgProxy: #REF!
Name cfgProxy: #REF!
Name cfgProxy: #REF!
Name cfgProxyPort: #REF!
Name cfgProxyPort: #REF!
Name cfgProxyPort: #REF!

Sheet rumus terdekat
A1: cek data | B1: x | C1: y | D1: BIGO SELATAN | E1: BOLAANG MONGONDOW UTARA | F1: BB 143.1 | G1: 0.89482 | H1: 123.26336
A2: isian kordinat | B2: 0.71572 | C2: 124.37167 | D2: BUYAT | E2: BOLAANG MONGONDOW TIMUR | F2: KMO 215 | G2: 0.85049599 | H2: 124.68857
A3: gardu terdetkat | B3: =LOOKUP(1,1/FREQUENCY(0,SIN((RADIANS($G:$G-$B$2))/2)^2+SIN((RADIANS($H:$H-$C$2))/2)^2*COS(RADIANS($G:$G))*COS(RADIANS($B$2))),$F:$F) -> KMO 12 | D3: BUYAT | E3: BOLAANG MONGONDOW TIMUR | F3: KMO 216 | G3: 0.85150701 | H3: 124.68964
A4: gardu terdetkat1 | B4: {=LOOKUP(1,1/FREQUENCY(0,SIN((RADIANS($G:$G-$B$2))/2)^1+SIN((RADIANS($H:$H-$C$2))/2)^2*COS(RADIANS($G:$G))*COS(RADIANS($B$2))),$F:$F)} -> KMO 12 | D4: BONGKUDAI | E4: BOLAANG MONGONDOW TIMUR | F4: KMO 12 | G4: 0.71572 | H4: 124.37167
A5: gardu terdetkat2 | B5: {=LOOKUP(1,1/FREQUENCY(0,SIN((RADIANS($G:$G-$B$2))/2)^3+SIN((RADIANS($H:$H-$C$2))/2)^2*COS(RADIANS($G:$G))*COS(RADIANS($B$2))),$F:$F)} -> KMO 12 | D5: BONGKUDAI | E5: BOLAANG MONGONDOW TIMUR | F5: KMO 15 | G5: 0.71509397 | H5: 124.37309
A6: gardu terdetkat3 | B6: {=LOOKUP(1,1/FREQUENCY(0,SIN((RADIANS($G:$G-$B$2))/2)^4+SIN((RADIANS($H:$H-$C$2))/2)^2*COS(RADIANS($G:$G))*COS(RADIANS($B$2))),$F:$F)} -> KMO 12 | D6: TOMBOLIKAT | E6: BOLAANG MONGONDOW TIMUR | F6: KMO 196 | G6: 0.77558601 | H6: 124.61767
A7: jurusan T Induk | D7: PINOLOSIAN TIMUR | E7: BOLAANG MONGONDOW SELATAN | F7: L-144 | G7: 0.45646 | H7: 124.42854
A8: cabang R1 | D8: TOBONGON | E8: BOLAANG MONGONDOW TIMUR | F8: KMO 31 | G8: 0.702353 | H8: 124.40488
A9: cabang R2 | D9: LANUD | E9: BOLAANG MONGONDOW TIMUR | F9: KMO 38 | G9: 0.65386802 | H9: 124.45435
A10: cabang R3 | D10: LANUD | E10: BOLAANG MONGONDOW TIMUR | F10: KMO 40 | G10: 0.656537 | H10: 124.46075
A11: cabang R4 | D11: NUANGAN | E11: BOLAANG MONGONDOW TIMUR | F11: KMO 64 | G11: 0.58212799 | H11: 124.52679
A12: cabang S1 | D12: NUANGAN | E12: BOLAANG MONGONDOW TIMUR | F12: KMO 65 | G12: 0.57849699 | H12: 124.5134
A13: cabang S2 | D13: PINASUNGKULAN | E13: MINAHASA SELATAN | F13: KMO 122 | G13: 0.79277599 | H13: 124.45316
A14: cabang S3 | D14: MAKAARUYEN | E14: MINAHASA SELATAN | F14: KMO 129 | G14: 0.80122799 | H14: 124.44716
A15: cabang S4 | D15: MAKAARUYEN | E15: MINAHASA SELATAN | F15: KMO 131 | G15: 0.80458701 | H15: 124.44593
D16: BOLAANG UKI | E16: BOLAANG MONGONDOW SELATAN | F16: L-087 | G16: 0.37527 | H16: 124.00867
D17: BOLAANG UKI | E17: BOLAANG MONGONDOW SELATAN | F17: L-089 | G17: 0.38067 | H17: 124.01775
A18: gardu terdetkatopsi 2 | B18: {=LOOKUP(1,1/FREQUENCY(0,MMULT(($G:$H-$B$2:$C$2)^2,{1;1})),$F:$F)} -> KMO 12 | D18: PINOLOSIAN TIMUR | E18: BOLAANG MONGONDOW SELATAN | F18: L-139 | G18: 0.45651 | H18: 124.40461
A19: pelanggan piutang terdekat | D19: KOTABUNAN | E19: BOLAANG MONGONDOW TIMUR | F19: KMO 207 | G19: 0.807311 | H19: 124.65518
A20: pelanggan piutang terdekat opsi 2 | D20: MOYONGKOTA | E20: BOLAANG MONGONDOW TIMUR | F20: KMO 3 | G20: 0.73105902 | H20: 124.35713
D21: MOYONGKOTA | E21: BOLAANG MONGONDOW TIMUR | F21: KMO 4 | G21: 0.72947103 | H21: 124.35571
D22: MOLOBOG | E22: BOLAANG MONGONDOW TIMUR | F22: KMO 49 | G22: 0.63827401 | H22: 124.52997
D23: MOLOBOG | E23: BOLAANG MONGONDOW TIMUR | F23: KMO 53 | G23: 0.65332598 | H23: 124.54971
D24: JIKO | E24: BOLAANG MONGONDOW TIMUR | F24: KMO 56 | G24: 0.62147599 | H24: 124.54624
D25: PALELON | E25: MINAHASA SELATAN | F25: KMO 133 | G25: 0.80663902 | H25: 124.43892
D26: WULURMAATUS | E26: MINAHASA SELATAN | F26: KMO 138 | G26: 0.81015199 | H26: 124.43267
D27: MOKOBANG | E27: MINAHASA SELATAN | F27: KMO 140 | G27: 0.84362203 | H27: 124.43693
D28: MOTONGKAT | E28: BOLAANG MONGONDOW TIMUR | F28: KMO 157 | G28: 0.66319901 | H28: 124.55881
D29: MODAYAG | E29: BOLAANG MONGONDOW TIMUR | F29: KMO 22 | G29: 0.710985 | H29: 124.38274
D30: LIBERIA | E30: BOLAANG MONGONDOW TIMUR | F30: KMO 84 | G30: 0.719455 | H30: 124.3939
D31: LANUD | E31: BOLAANG MONGONDOW TIMUR | F31: KMO 42 | G31: 0.65116602 | H31: 124.46834
D32: BAI | E32: BOLAANG MONGONDOW TIMUR | F32: KMO 47 | G32: 0.63456899 | H32: 124.51112
... D1363: LOLAK | E1363: BOLAANG MONGONDOW INDUK | F1363: NL 052 | G1363: 0.86078 | H1363: 123.93939

Sheet gardu up3 kotamobagu
A1: GARDUID | B1: UID_W | C1: UP3_2D | D1: ULP | E1: CXPENYULANG | F1: CXUNIT | G1: LOCATION | H1: DESCRIPTION | I1: STATUS | J1: OWNERSYSID | K1: EXTERNALREFID | L1: TUJDNUMBER | M1: ASSETCLASSHI | N1: SADDRESSCODE | O1: CHANGEBY | P1: CHANGEDATE | Q1: LONGITUDEX | R1: LATITUDEY | S1: STREETADDRESS | T1: FORMATTEDADDRESS | U1: CITY | V1: ISASSET | W1: JENIS_PELAYANAN | X1: KODE_PERALATAN | Y1: OWNER_PEMELIHARAAN | Z1: STATUS_KEPEMILIKAN | AA1: STATUS_RC | AB1: TYPE_BANGUNAN_GARDU | AC1: TYPE_GARDU | AD1: ROWSTAMP | AE1: INSDATE
A2: 518040 | B2: UIW.7301 | C2: UP3.7314 | D2: ULP.31740 | E2: 11053186 | F2: ULP.31740 | G2: GD01.31305284 | H2: BB 143.1 | I2: OPERATING | L2: 73GD0131305284 | M2: 3 | N2: SA2734355 | O2: ZAKKI.MUBAROK | P2: 2021-08-20-07.30.15.321000 | Q2: 123.26336 | R2: 0.89482 | S2: BIGO SELATAN | T2: BIGO SELATAN | U2: BOLAANG MONGONDOW UTARA | AD2: 6070887223 | AE2: 2023-08-28-18.43.56.776156
A3: 518073 | B3: UIW.7301 | C3: UP3.7314 | D3: ULP.31730 | E3: 11053199 | F3: ULP.31730 | G3: GD01.22185513 | H3: KMO 215 | I3: OPERATING | L3: 73GD0122185513 | M3: 3 | N3: SA26984120 | O3: MXINTADM | P3: 2020-09-24-17.49.19.148000 | Q3: 124.68857 | R3: 0.85049599 | S3: JLN. RATAHAN-KOTAMOBAGU | T3: BUYAT | U3: BOLAANG MONGONDOW TIMUR | V3: 1 | W3: Umum | Z3: PLN | AA3: TIDAK ADA | AB3: 0 | AC3: Gardu Cantol | AD3: 6070872770 | AE3: 2023-08-28-18.43.56.776156
A4: 518074 | B4: UIW.7301 | C4: UP3.7314 | D4: ULP.31730 | E4: 11053199 | F4: ULP.31730 | G4: GD01.22185514 | H4: KMO 216 | I4: OPERATING | L4: 73GD0122185514 | M4: 3 | N4: SA26984121 | O4: MXINTADM | P4: 2020-08-25-19.01.18.274000 | Q4: 124.68964 | R4: 0.85150701 | S4: JLN. RATAHAN-KOTAMOBAGU | T4: BUYAT | U4: BOLAANG MONGONDOW TIMUR | V4: 1 | W4: Umum | Z4: PLN | AA4: TIDAK ADA | AB4: 0 | AC4: Gardu Cantol | AD4: 6070872771 | AE4: 2023-08-28-18.43.56.776156
A5: 518415 | B5: UIW.7301 | C5: UP3.7314 | D5: ULP.31730 | E5: 11053198 | F5: ULP.31730 | G5: GD01.14040072 | H5: KMO 12 | I5: OPERATING | L5: 73GD0114040072 | M5: 3 | N5: SA15533570 | O5: MXINTADM | P5: 2020-08-25-19.01.06.624000 | Q5: 124.37167 | R5: 0.71572 | S5: JLN. RATAHAN-KOTAMOBAGU | T5: BONGKUDAI | U5: BOLAANG MONGONDOW TIMUR | V5: 1 | W5: Umum | Z5: PLN | AA5: TIDAK ADA | AB5: 0 | AC5: Gardu Cantol | AD5: 6070871502 | AE5: 2023-08-28-18.43.56.776156
A6: 518416 | B6: UIW.7301 | C6: UP3.7314 | D6: ULP.31730 | E6: 11053198 | F6: ULP.31730 | G6: GD01.14040075 | H6: KMO 15 | I6: OPERATING | L6: 73GD0114040075 | M6: 3 | N6: SA15533573 | O6: MXINTADM | P6: 2020-08-25-19.01.07.046000 | Q6: 124.37309 | R6: 0.71509397 | S6: JLN. RATAHAN-KOTAMOBAGU | T6: BONGKUDAI | U6: BOLAANG MONGONDOW TIMUR | V6: 1 | W6: Umum | Z6: PLN | AA6: TIDAK ADA | AB6: 0 | AC6: Gardu Cantol | AD6: 6070871505 | AE6: 2023-08-28-18.43.56.776156
A7: 518418 | B7: UIW.7301 | C7: UP3.7314 | D7: ULP.31730 | E7: 11053199 | F7: ULP.31730 | G7: GD01.14040085 | H7: KMO 196 | I7: OPERATING | L7: 73GD0114040085 | M7: 3 | N7: SA15533583 | O7: MXINTADM | P7: 2020-08-25-19.01.19.785000 | Q7: 124.61767 | R7: 0.77558601 | S7: JLN. RATAHAN-KOTAMOBAGU | T7: TOMBOLIKAT | U7: BOLAANG MONGONDOW TIMUR | V7: 1 | W7: Umum | Z7: PLN | AA7: TIDAK ADA | AB7: 0 | AC7: Gardu Portal | AD7: 6070871511 | AE7: 2023-08-28-18.43.56.776156
A8: 518439 | B8: UIW.7301 | C8: UP3.7314 | D8: ULP.31750 | E8: 11053210 | F8: ULP.31750 | G8: GD01.14039406 | H8: L-144 | I8: OPERATING | L8: 73GD0114039406 | M8: 3 | N8: SA15532904 | O8: MXINTADM | P8: 2020-08-01-06.39.33.236000 | Q8: 124.42854 | R8: 0.45646 | S8: POSILAGON | T8: PINOLOSIAN TIMUR | U8: BOLAANG MONGONDOW SELATAN | V8: 1 | W8: Umum | Z8: PLN | AA8: TIDAK ADA | AB8: 0 | AC8: Gardu Cantol | AD8: 6070897489 | AE8: 2023-08-28-18.43.56.776156
A9: 518476 | B9: UIW.7301 | C9: UP3.7314 | D9: ULP.31730 | E9: 11053197 | F9: ULP.31730 | G9: GD01.14039020 | H9: KMO 31 | I9: OPERATING | L9: 73GD0114039020 | M9: 3 | N9: SA15532518 | O9: MXINTADM | P9: 2020-08-25-19.00.35.271000 | Q9: 124.40488 | R9: 0.702353 | S9: JLN. RATAHAN-KOTAMOBAGU | T9: TOBONGON | U9: BOLAANG MONGONDOW TIMUR | V9: 1 | W9: Umum | Z9: PLN | AA9: TIDAK ADA | AB9: 0 | AC9: Gardu Cantol | AD9: 6070871355 | AE9: 2023-08-28-18.43.56.776156
A10: 518477 | B10: UIW.7301 | C10: UP3.7314 | D10: ULP.31730 | E10: 11053197 | F10: ULP.31730 | G10: GD01.14039027 | H10: KMO 38 | I10: OPERATING | L10: 73GD0114039027 | M10: 3 | N10: SA15532525 | O10: MXINTADM | P10: 2020-08-25-19.00.34.945000 | Q10: 124.45435 | R10: 0.65386802 | S10: JLN. RATAHAN-KOTAMOBAGU | T10: LANUD | U10: BOLAANG MONGONDOW TIMUR | V10: 1 | W10: Umum | Z10: PLN | AA10: TIDAK ADA | AB10: 0 | AC10: Gardu Cantol | AD10: 6070871361 | AE10: 2023-08-28-18.43.56.776156
A11: 518478 | B11: UIW.7301 | C11: UP3.7314 | D11: ULP.31730 | E11: 11053197 | F11: ULP.31730 | G11: GD01.14039029 | H11: KMO 40 | I11: OPERATING | L11: 73GD0114039029 | M11: 3 | N11: SA15532527 | O11: MXINTADM | P11: 2020-08-25-19.00.35.289000 | Q11: 124.46075 | R11: 0.656537 | S11: JLN. RATAHAN-KOTAMOBAGU | T11: LANUD | U11: BOLAANG MONGONDOW TIMUR | V11: 1 | W11: Umum | Z11: PLN | AA11: TIDAK ADA | AB11: 0 | AC11: Gardu Cantol | AD11: 6070871363 | AE11: 2023-08-28-18.43.56.776156
A12: 518479 | B12: UIW.7301 | C12: UP3.7314 | D12: ULP.31730 | E12: 11053197 | F12: ULP.31730 | G12: GD01.14039053 | H12: KMO 64 | I12: OPERATING | L12: 73GD0114039053 | M12: 3 | N12: SA15532551 | O12: MXINTADM | P12: 2020-08-25-19.00.35.515000 | Q12: 124.52679 | R12: 0.58212799 | S12: JLN. TRANS LINGKAR SELATAN | T12: NUANGAN | U12: BOLAANG MONGONDOW TIMUR | V12: 1 | W12: Khusus | Z12: PLN | AA12: TIDAK ADA | AB12: 0 | AC12: Gardu Portal | AD12: 6070871386 | AE12: 2023-08-28-18.43.56.776156
A13: 518480 | B13: UIW.7301 | C13: UP3.7314 | D13: ULP.31730 | E13: 11053197 | F13: ULP.31730 | G13: GD01.14039054 | H13: KMO 65 | I13: OPERATING | L13: 73GD0114039054 | M13: 3 | N13: SA15532552 | O13: MXINTADM | P13: 2020-08-25-19.00.34.535000 | Q13: 124.5134 | R13: 0.57849699 | S13: JLN. TRANS LINGKAR SELATAN | T13: NUANGAN | U13: BOLAANG MONGONDOW TIMUR | V13: 1 | W13: Umum | Z13: PLN | AA13: TIDAK ADA | AB13: 0 | AC13: Gardu Portal | AD13: 6070871387 | AE13: 2023-08-28-18.43.56.776156
A14: 518481 | B14: UIW.7301 | C14: UP3.7314 | D14: ULP.31730 | E14: 11053194 | F14: ULP.31730 | G14: GD01.14039100 | H14: KMO 122 | I14: OPERATING | L14: 73GD0114039100 | M14: 3 | N14: SA15532598 | O14: MXINTADM | P14: 2020-08-25-19.00.04.255000 | Q14: 124.45316 | R14: 0.79277599 | S14: JLN. AMURANG KOTAMOBAGU | T14: PINASUNGKULAN | U14: MINAHASA SELATAN | V14: 1 | W14: Umum | Z14: PLN | AA14: TIDAK ADA | AB14: 0 | AC14: Gardu Portal | AD14: 6070871431 | AE14: 2023-08-28-18.43.56.776156
... A71: 521619 | B71: UIW.7301 | C71: UP3.7314 | D71: ULP.31750 | E71: 11053210 | F71: ULP.31750 | G71: GD01.14039395 | H71: L-133 | I71: OPERATING | L71: 73GD0114039395 | M71: 3 | N71: SA15532893 | O71: MXINTADM | P71: 2020-08-01-06.36.24.509000 | Q71: 124.30897 | R71: 0.44014 | S71: MATANDOI | T71: PINOLOSIAN TIMUR | U71: BOLAANG MONGONDOW SELATAN | V71: 1 | W71: Umum | Z71: PLN | AA71: TIDAK ADA | AB71: 0 | AC71: Gardu Cantol | AD71: 6070897478 | AE71: 2023-08-28-18.43.56.776156
A72: 521995 | B72: UIW.7301 | C72: UP3.7314 | D72: ULP.31760 | F72: ULP.31760 | G72: GD01.22417877 | H72: K-278.4 | I72: OPERATING | L72: 73GD0122417877 | M72: 3 | N72: SA2668186 | O72: MXINTADM | P72: 2021-04-26-19.10.16.253000 | Q72: 124.26966 | R72: 0.601095 | S72: LOLAYAN | T72: BOLAANG MONGONDOW | U72: KOTAMOBAGU | V72: 1 | W72: Umum | Z72: PLN | AA72: TIDAK ADA | AB72: PORTAL | AC72: Gardu Portal | AD72: 6070899417 | AE72: 2023-08-28-18.43.56.776156
A73: 522208 | B73: UIW.7301 | C73: UP3.7314 | D73: ULP.31730 | E73: 11053199 | F73: ULP.31730 | G73: GD01.45596107 | H73: KMO 210.1 | I73: OPERATING | L73: 73GD0145596107 | M73: 3 | N73: SA51771315 | O73: AI.FAUZIAH | P73: 2021-11-02-14.44.01.397000 | Q73: 124.65477 | R73: 0.81178 | S73: JLN. RATAHAN-KOTAMOBAGU | T73: KOTABUNAN | U73: BOLAANG MONGONDOW TIMUR | V73: 1 | W73: Umum | Z73: PLN | AA73: TIDAK ADA | AC73: Gardu Portal | AD73: 6070872985 | AE73: 2023-08-28-18.43.56.776156
A74: 522209 | B74: UIW.7301 | C74: UP3.7314 | D74: ULP.31730 | E74: 11053199 | F74: ULP.31730 | G74: GD01.45688477 | H74: KMO 216.1 | I74: OPERATING | L74: 73GD0145688477 | M74: 3 | N74: SA51771919 | O74: ZAKKI.MUBAROK | P74: 2021-11-16-13.30.04.561000 | Q74: 124.6896 | R74: 0.85296 | S74: JLN. RATAHAN-KOTAMOBAGU | T74: BUYAT | U74: BOLAANG MONGONDOW TIMUR | V74: 1 | W74: Umum | Z74: PLN | AA74: TIDAK ADA | AC74: Gardu Portal | AD74: 6070872990 | AE74: 2023-08-28-18.43.56.776156
A75: 522219 | B75: UIW.7301 | C75: UP3.7314 | D75: ULP.31760 | E75: 11053154 | F75: ULP.31760 | G75: GD01.54193889 | H75: K-249.2 | I75: OPERATING | L75: 73GD0154193889 | M75: 3 | N75: SA51985987 | O75: ZAKKI.MUBAROK | P75: 2022-03-02-15.11.59.627000 | Q75: 124.32295 | R75: 0.70674 | S75: POYOWA BESAR | T75: KOTAMOBAGU SELATAN | U75: KOTAMOBAGU | W75: Umum | Z75: PLN | AA75: TIDAK ADA | AC75: Gardu Portal | AD75: 6070914854 | AE75: 2023-08-28-18.43.56.776156
A76: 522220 | B76: UIW.7301 | C76: UP3.7314 | D76: ULP.31760 | E76: 11053151 | F76: ULP.31760 | G76: GD01.54215633 | H76: K-017.1 | I76: OPERATING | L76: 73GD0154215633 | M76: 3 | N76: SA51986159 | O76: ZAKKI.MUBAROK | P76: 2022-03-02-15.11.59.800000 | Q76: 124.27882 | R76: 0.717361 | S76: JL TRANS SULAWESI | T76: MONGKONAI | U76: KOTAMOBAGU | W76: Umum | Z76: PLN | AA76: ADA | AC76: Gardu Portal | AD76: 6070914856 | AE76: 2023-08-28-18.43.56.776156
A77: 522267 | B77: UIW.7301 | C77: UP3.7314 | D77: ULP.31740 | E77: 11053186 | F77: ULP.31740 | G77: GD01.29040878 | H77: BB 150.1 | I77: OPERATING | L77: 73GD0129040878 | M77: 3 | N77: SA2733314 | O77: ZAKKI.MUBAROK | P77: 2021-08-13-09.27.46.282000 | Q77: 123.27865 | R77: 0.90469 | S77: KUALA | T77: KUALA | U77: BOLAANG MONGONDOW UTARA | V77: 1 | W77: Umum | Z77: PLN | AA77: TIDAK ADA | AC77: Gardu Portal | AD77: 6070887204 | AE77: 2023-08-28-18.43.56.776156
A78: 522289 | B78: UIW.7301 | C78: UP3.7314 | D78: ULP.31730 | E78: 11053199 | F78: ULP.31730 | G78: GD01.22185532 | H78: GARDU AMAL MAKALALAG | I78: OPERATING | L78: 73GD0122185532 | M78: 1 | N78: SA26984139 | O78: MXINTADM | P78: 2020-09-24-17.48.39.524000 | Q78: 124.53907 | R78: 0.679236 | S78: NUANGAN | T78: ATOGA | U78: BOLAANG MONGONDOW TIMUR | V78: 1 | W78: Khusus | Z78: PLN | AA78: ADA | AB78: 0 | AC78: Gardu Beton | AD78: 6070872784 | AE78: 2023-08-28-18.43.56.776156
A79: 522592 | B79: UIW.7301 | C79: UP3.7314 | D79: ULP.31730 | E79: 11053199 | F79: ULP.31730 | G79: GD01.14039839 | H79: KMO 178 | I79: OPERATING | L79: 73GD0114039839 | M79: 3 | N79: SA15533337 | O79: MXINTADM | P79: 2020-08-25-19.01.19.234000 | Q79: 124.61929 | R79: 0.754089 | S79: JLN. RATAHAN-KOTAMOBAGU | T79: TUTUYAN | U79: BOLAANG MONGONDOW TIMUR | V79: 1 | W79: Umum | Z79: PLN | AA79: TIDAK ADA | AB79: 0 | AC79: Gardu Cantol | AD79: 6070871475 | AE79: 2023-08-28-18.43.56.776156
A80: 522593 | B80: UIW.7301 | C80: UP3.7314 | D80: ULP.31730 | E80: 11053199 | F80: ULP.31730 | G80: GD01.14039843 | H80: KMO 182 | I80: OPERATING | L80: 73GD0114039843 | M80: 3 | N80: SA15533341 | O80: MXINTADM | P80: 2020-08-25-19.01.18.940000 | Q80: 124.61245 | R80: 0.75969499 | S80: JLN. RATAHAN-KOTAMOBAGU | T80: TUTUYAN | U80: BOLAANG MONGONDOW TIMUR | V80: 1 | W80: Umum | Z80: PLN | AA80: TIDAK ADA | AB80: 0 | AC80: Gardu Portal | AD80: 6070871479 | AE80: 2023-08-28-18.43.56.776156
A81: 522594 | B81: UIW.7301 | C81: UP3.7314 | D81: ULP.31730 | E81: 11053199 | F81: ULP.31730 | G81: GD01.14039844 | H81: KMO 183 | I81: OPERATING | L81: 73GD0114039844 | M81: 3 | N81: SA15533342 | O81: MXINTADM | P81: 2020-08-25-19.01.19.472000 | Q81: 124.61041 | R81: 0.75449401 | S81: JLN. RATAHAN-KOTAMOBAGU | T81: TUTUYAN | U81: BOLAANG MONGONDOW TIMUR | V81: 1 | W81: Umum | Z81: PLN | AA81: TIDAK ADA | AB81: 0 | AC81: Gardu Cantol | AD81: 6070871480 | AE81: 2023-08-28-18.43.56.776156
A82: 522624 | B82: UIW.7301 | C82: UP3.7314 | D82: ULP.31750 | E82: 11053210 | F82: ULP.31750 | G82: GD01.14039379 | H82: L-117 | I82: OPERATING | L82: 73GD0114039379 | M82: 3 | N82: SA15532877 | O82: ZAKKI.MUBAROK | P82: 2022-02-10-13.33.56.812000 | Q82: 124.13897 | R82: 0.40553 | S82: KOMBOT | T82: PINOLOSIAN | U82: BOLAANG MONGONDOW SELATAN | V82: 1 | W82: Umum | Z82: PLN | AA82: TIDAK ADA | AB82: 0 | AC82: Gardu Cantol | AD82: 6070897463 | AE82: 2023-08-28-18.43.56.776156
A83: 522625 | B83: UIW.7301 | C83: UP3.7314 | D83: ULP.31750 | E83: 11053210 | F83: ULP.31750 | G83: GD01.14039380 | H83: L-118 | I83: OPERATING | L83: 73GD0114039380 | M83: 3 | N83: SA15532878 | O83: MXINTADM | P83: 2020-08-01-06.36.06.990000 | Q83: 124.14255 | R83: 0.40499 | S83: KOMBOT | T83: PINOLOSIAN | U83: BOLAANG MONGONDOW SELATAN | V83: 1 | W83: Umum | Z83: PLN | AA83: TIDAK ADA | AB83: 0 | AC83: Gardu Cantol | AD83: 6070897464 | AE83: 2023-08-28-18.43.56.776156
A84: 522626 | B84: UIW.7301 | C84: UP3.7314 | D84: ULP.31750 | E84: 11053210 | F84: ULP.31750 | G84: GD01.14039387 | H84: L-126 | I84: OPERATING | L84: 73GD0114039387 | M84: 3 | N84: SA15532885 | O84: MXINTADM | P84: 2020-08-01-06.27.08.084000 | Q84: 124.25118 | R84: 0.42147 | S84: ADOW | T84: PINOLOSIAN SELATAN | U84: BOLAANG MONGONDOW SELATAN | V84: 1 | W84: Umum | Z84: PLN | AA84: TIDAK ADA | AB84: 0 | AC84: Gardu Cantol | AD84: 6070897471 | AE84: 2023-08-28-18.43.56.776156
A85: 522627 | B85: UIW.7301 | C85: UP3.7314 | D85: ULP.31750 | E85: 11053210 | F85: ULP.31750 | G85: GD01.14039389 | H85: L-127 | I85: OPERATING | L85: 73GD0114039389 | M85: 3 | N85: SA15532887 | O85: MXINTADM | P85: 2020-08-01-00.56.32.683000 | Q85: 124.26168 | R85: 0.43334 | S85: TOROSIK | T85: PINOLOSIAN SELATAN | U85: BOLAANG MONGONDOW SELATAN | V85: 1 | W85: Umum | Z85: PLN | AA85: TIDAK ADA | AB85: 0 | AC85: Gardu Cantol | AD85: 6070897472 | AE85: 2023-08-28-18.43.56.776156
A86: 522636 | B86: UIW.7301 | C86: UP3.7314 | D86: ULP.31750 | E86: 11053208 | F86: ULP.31750 | G86: GD01.14039573 | H86: L-097 | I86: OPERATING | L86: 73GD0114039573 | M86: 3 | N86: SA15533071 | O86: MXINTADM | P86: 2020-08-01-00.56.35.260000 | Q86: 124.04204 | R86: 0.37694 | S86: TABILAA | T86: BOLAANG UKI | U86: BOLAANG MONGONDOW SELATAN | V86: 1 | W86: Umum | Z86: PLN | AA86: TIDAK ADA | AB86: 0 | AC86: Gardu Portal | AD86: 6070897494 | AE86: 2023-08-28-18.43.56.776156
A87: 522637 | B87: UIW.7301 | C87: UP3.7314 | D87: ULP.31750 | E87: 11053208 | F87: ULP.31750 | G87: GD01.14039574 | H87: L-098 | I87: OPERATING | L87: 73GD0114039574 | M87: 3 | N87: SA15533072 | O87: MXINTADM | P87: 2020-08-01-06.35.31.884000 | Q87: 124.04545 | R87: 0.37945 | S87: TABILAA | T87: BOLAANG UKI | U87: BOLAANG MONGONDOW SELATAN | V87: 1 | W87: Umum | Z87: PLN | AA87: TIDAK ADA | AB87: 0 | AC87: Gardu Portal | AD87: 6070897495 | AE87: 2023-08-28-18.43.56.776156
A88: 522653 | B88: UIW.7301 | C88: UP3.7314 | D88: ULP.31730 | E88: 11053199 | F88: ULP.31730 | G88: GD01.14039830 | H88: KMO 169 | I88: OPERATING | L88: 73GD0114039830 | M88: 3 | N88: SA15533328 | O88: MXINTADM | P88: 2020-08-25-19.01.19.203000 | Q88: 124.59332 | R88: 0.72650701 | S88: JLN. RATAHAN-KOTAMOBAGU | T88: TOGIT | U88: BOLAANG MONGONDOW TIMUR | V88: 1 | W88: Umum | Z88: PLN | AA88: TIDAK ADA | AB88: 0 | AC88: Gardu Cantol | AD88: 6070871466 | AE88: 2023-08-28-18.43.56.776156
A89: 522654 | B89: UIW.7301 | C89: UP3.7314 | D89: ULP.31730 | E89: 11053199 | F89: ULP.31730 | G89: GD01.14039837 | H89: KMO 176 | I89: OPERATING | L89: 73GD0114039837 | M89: 3 | N89: SA15533335 | O89: MXINTADM | P89: 2020-08-25-19.01.19.753000 | Q89: 124.61211 | R89: 0.75546998 | S89: JLN. RATAHAN-KOTAMOBAGU | T89: TUTUYAN | U89: BOLAANG MONGONDOW TIMUR | V89: 1 | W89: Umum | Z89: PLN | AA89: TIDAK ADA | AB89: 0 | AC89: Gardu Cantol | AD89: 6070871473 | AE89: 2023-08-28-18.43.56.776156
... A101: 522684 | B101: UIW.7301 | C101: UP3.7314 | D101: ULP.31750 | E101: 11053210 | F101: ULP.31750 | G101: GD01.14039377 | H101: L-115 | I101: OPERATING | L101: 73GD0114039377 | M101: 3 | N101: SA15532875 | O101: MXINTADM | P101: 2020-08-01-06.36.16.504000 | Q101: 124.11709 | R101: 0.39582 | S101: TOLOTOYON | T101: PINOLOSIAN | U101: BOLAANG MONGONDOW SELATAN | V101: 1 | W101: Umum | Z101: PLN | AA101: TIDAK ADA | AB101: 0 | AC101: Gardu Cantol | AD101: 6070897461 | AE101: 2023-08-28-18.43.56.776156
A102: 523260 | B102: UIW.7301 | C102: UP3.7314 | D102: ULP.31720 | E102: 11053136 | F102: ULP.31720 | G102: GD01.35587446 | H102: NP 031.1 | I102: OPERATING | L102: 73GD0135587446 | M102: 3 | N102: SA2745729 | O102: ZAKKI.MUBAROK | P102: 2021-09-20-14.28.48.101000 | Q102: 124.30586 | R102: 1.018524 | S102: POIGAR MINAHASA | T102: POIGAR MINAHASA | U102: MINAHASA SELATAN | V102: 1 | W102: Umum | Z102: PLN | AA102: TIDAK ADA | AC102: Gardu Portal | AD102: 6070826068 | AE102: 2023-08-28-18.43.56.776156
A103: 523261 | B103: UIW.7301 | C103: UP3.7314 | D103: ULP.31720 | E103: 11053136 | F103: ULP.31720 | G103: GD01.35673839 | H103: N 017.2 | I103: OPERATING | L103: 73GD0135673839 | M103: 3 | N103: SA46877716 | O103: ZAKKI.MUBAROK | P103: 2021-10-14-07.36.13.706000 | Q103: 124.18112 | R103: 0.944307 | S103: LOLAN | T103: LOLAN | U103: BOLAANG MONGONDOW INDUK | V103: 1 | W103: Umum | Z103: PLN | AA103: TIDAK ADA | AC103: Gardu Portal | AD103: 6070826113 | AE103: 2023-08-28-18.43.56.776156
A104: 523269 | B104: UIW.7301 | C104: UP3.7314 | D104: ULP.31760 | F104: ULP.31760 | G104: GD01.51320721 | H104: K-264.1 | I104: OPERATING | L104: 73GD0151320721 | M104: 3 | N104: SA2667884 | O104: ZAKKI.MUBAROK | P104: 2022-09-02-13.48.33.319000 | Q104: 124.2754 | R104: 0.6815 | S104: JL.RAYA DESA | T104: BOLAANG MONGONDOW | U104: KOTAMOBAGU | V104: 1 | W104: Umum | Z104: PLN | AA104: TIDAK ADA | AC104: Gardu Portal | AD104: 6285934090 | AE104: 2023-08-28-18.43.56.776156
A105: 523280 | B105: UIW.7301 | C105: UP3.7314 | D105: ULP.31710 | E105: 11053138 | F105: ULP.31710 | G105: GD01.54464688 | H105: M 36.1 | I105: OPERATING | L105: 73GD0154464688 | M105: 3 | N105: SA51988764 | O105: ZAKKI.MUBAROK | P105: 2022-03-08-12.41.20.099000 | Q105: 124.11906 | R105: 0.697311 | S105: BOLAANG MONGONDOW | T105: BOLAANG MONGONDOW | U105: BOLAANG MONGONDOW INDUK | W105: Campuran | Z105: PLN | AA105: TIDAK ADA | AC105: Gardu Cantol | AD105: 6070820614 | AE105: 2023-08-28-18.43.56.776156
A106: 523312 | B106: UIW.7301 | C106: UP3.7314 | D106: ULP.31730 | F106: ULP.31730 | G106: GD01.24407034 | H106: KMO 8.1 | I106: OPERATING | L106: 73GD0124407034 | M106: 3 | N106: SA30464296 | O106: MXINTADM | P106: 2021-04-26-19.10.08.533000 | Q106: 124.36318 | R106: 0.723419 | S106: JLN. RATAHAN-KOTAMOBAGU | T106: BANGUNAN WUWUK | U106: BOLAANG MONGONDOW TIMUR | W106: Umum | Z106: PLN | AA106: TIDAK ADA | AC106: Gardu Cantol | AD106: 6070872882 | AE106: 2023-08-28-18.43.56.776156
A107: 523347 | B107: UIW.7301 | C107: UP3.7314 | D107: ULP.31730 | E107: 11053199 | F107: ULP.31730 | G107: GD01.22185523 | H107: KMO 224 | I107: OPERATING | L107: 73GD0122185523 | M107: 3 | N107: SA26984130 | O107: MXINTADM | P107: 2020-08-25-19.01.18.454000 | Q107: 124.62735 | R107: 0.85486502 | S107: JLN. RATAHAN-KOTAMOBAGU | T107: BUKAKA | U107: BOLAANG MONGONDOW TIMUR | V107: 1 | W107: Umum | Z107: PLN | AA107: TIDAK ADA | AB107: 0 | AC107: Gardu Cantol | AD107: 6070872780 | AE107: 2023-08-28-18.43.56.776156
...

Sheet CEK INFO DETAIL
A1: PERCEPATAN LAYANAN PB PD ONDESK | I1: BIGO SELATAN | J1: BOLAANG MONGONDOW UTARA | K1: BB 143.1 | L1: 0.89482 | M1: 123.26336
A2: CEK BAGIAN TEKNIS | I2: BUYAT | J2: BOLAANG MONGONDOW TIMUR | K2: KMO 215 | L2: 0.85049599 | M2: 124.68857
A3: CEK KORIDINAT | I3: BUYAT | J3: BOLAANG MONGONDOW TIMUR | K3: KMO 216 | L3: 0.85150701 | M3: 124.68964
A4: X | B4: Y | C4: NAMA PERMOHONAN PELANGGAN | D4: NO AGENDA | F4: DAYA | G4: FASA | I4: BONGKUDAI | J4: BOLAANG MONGONDOW TIMUR | K4: KMO 12 | L4: 0.71572 | M4: 124.37167
A5: 0.7429 | B5: 124.31199 | C5: IBRAHIM MIDU | D5: 317100512510082477 | F5: 1300 | G5: =VLOOKUP(F5,'DATA MATERIAL TEL TEK'!$C:$D,2,0) -> 1 FASA | I5: BONGKUDAI | J5: BOLAANG MONGONDOW TIMUR | K5: KMO 15 | L5: 0.71509397 | M5: 124.37309
A6: MONITORING GARDU 20 KV | F6: SATUAN | G6: KETERANGAN | H6: PIC | I6: TOMBOLIKAT | J6: BOLAANG MONGONDOW TIMUR | K6: KMO 196 | L6: 0.77558601 | M6: 124.61767
A7: gardu terdetkat | B7: =LOOKUP(1,1/FREQUENCY(0,6371*2*ASIN(SQRT(SIN(RADIANS($L:$L-$A$5)/2)^2+COS(RADIANS($A$5))*COS(RADIANS($L:$L))*SIN(RADIANS($M:$M-$B$5)/2)^2))),$K:$K) -> K-160 | F7: NAMA GARDU | H7: TEK | I7: PINOLOSIAN TIMUR | J7: BOLAANG MONGONDOW SELATAN | K7: L-144 | L7: 0.45646 | M7: 124.42854
A8: gardu terdetkat1 | B8: =LOOKUP(1,1/FREQUENCY(0,SIN(RADIANS($L:$L-$A$5)/2)^1+SIN(RADIANS($M:$M-$B$5)/2)^2*COS(RADIANS($L:$L))*COS(RADIANS($A$5))),$K:$K) -> K-067 | F8: NAMA GARDU | H8: TEK | I8: TOBONGON | J8: BOLAANG MONGONDOW TIMUR | K8: KMO 31 | L8: 0.702353 | M8: 124.40488
A9: gardu terdetkat2 | B9: =LOOKUP(1,1/FREQUENCY(0,SIN(RADIANS($L:$L-$A$5)/2)^3+SIN(RADIANS($M:$M-$B$5)/2)^2*COS(RADIANS($L:$L))*COS(RADIANS($A$5))),$K:$K) -> K-160 | F9: NAMA GARDU | H9: TEK | I9: LANUD | J9: BOLAANG MONGONDOW TIMUR | K9: KMO 38 | L9: 0.65386802 | M9: 124.45435
A10: gardu terdetkat3 | B10: {=LOOKUP(1,1/FREQUENCY(0,SIN((RADIANS($L:$L-$A$5))/2)^4+SIN((RADIANS($M:$M-$B$5))/2)^2*COS(RADIANS($L:$L))*COS(RADIANS($A$5))),$K:$K)} -> K-160 | F10: NAMA GARDU | H10: TEK | I10: LANUD | J10: BOLAANG MONGONDOW TIMUR | K10: KMO 40 | L10: 0.656537 | M10: 124.46075
A11: jurusan Induk R | B11: =VLOOKUP($B$7,'DATA PENGEUKURAN GARDU'!$H:$BV,10,0) -> 18 | F11: A | H11: TEK | I11: NUANGAN | J11: BOLAANG MONGONDOW TIMUR | K11: KMO 64 | L11: 0.58212799 | M11: 124.52679
A12: jurusan Induk S | B12: =VLOOKUP($B$7,'DATA PENGEUKURAN GARDU'!$H:$BV,12,0) -> 6 | F12: A | H12: TEK | I12: NUANGAN | J12: BOLAANG MONGONDOW TIMUR | K12: KMO 65 | L12: 0.57849699 | M12: 124.5134
A13: jurusan Induk T | B13: =VLOOKUP($B$7,'DATA PENGEUKURAN GARDU'!$H:$BV,14,0) -> 7 | F13: A | H13: TEK | I13: PINASUNGKULAN | J13: MINAHASA SELATAN | K13: KMO 122 | L13: 0.79277599 | M13: 124.45316
A14: cabang R1 | B14: =VLOOKUP($B$7,'DATA PENGEUKURAN GARDU'!$H:$BV,20,0) -> 10 | F14: A | H14: TEK | I14: MAKAARUYEN | J14: MINAHASA SELATAN | K14: KMO 129 | L14: 0.80122799 | M14: 124.44716
A15: cabang S1 | B15: =VLOOKUP($B$7,'DATA PENGEUKURAN GARDU'!$H:$BV,22,0) -> 0 | F15: A | H15: TEK | I15: MAKAARUYEN | J15: MINAHASA SELATAN | K15: KMO 131 | L15: 0.80458701 | M15: 124.44593
A16: cabang T1 | B16: =VLOOKUP($B$7,'DATA PENGEUKURAN GARDU'!$H:$BV,24,0) -> 0 | F16: A | H16: TEK | I16: BOLAANG UKI | J16: BOLAANG MONGONDOW SELATAN | K16: L-087 | L16: 0.37527 | M16: 124.00867
A17: cabang R2 | B17: =VLOOKUP($B$7,'DATA PENGEUKURAN GARDU'!$H:$BV,29,0) -> 8 | F17: A | H17: TEK | I17: BOLAANG UKI | J17: BOLAANG MONGONDOW SELATAN | K17: L-089 | L17: 0.38067 | M17: 124.01775
A18: cabang S2 | B18: =VLOOKUP($B$7,'DATA PENGEUKURAN GARDU'!$H:$BV,31,0) -> 7 | F18: A | H18: TEK | I18: PINOLOSIAN TIMUR | J18: BOLAANG MONGONDOW SELATAN | K18: L-139 | L18: 0.45651 | M18: 124.40461
A19: cabang T2 | B19: =VLOOKUP($B$7,'DATA PENGEUKURAN GARDU'!$H:$BV,33,0) -> 7 | F19: A
A20: cabang R3 | B20: =VLOOKUP($B$7,'DATA PENGEUKURAN GARDU'!$H:$BV,38,0) -> 0 | F20: A
A21: cabang S3 | B21: =VLOOKUP($B$7,'DATA PENGEUKURAN GARDU'!$H:$BV,40,0) -> 0 | F21: A
A22: cabang T3 | B22: =VLOOKUP($B$7,'DATA PENGEUKURAN GARDU'!$H:$BV,42,0) -> 0 | F22: A | H22: TEK | I22: KOTABUNAN | J22: BOLAANG MONGONDOW TIMUR | K22: KMO 207 | L22: 0.807311 | M22: 124.65518
A23: cabang R4 | B23: =VLOOKUP($B$7,'DATA PENGEUKURAN GARDU'!$H:$BV,42,0) -> 0
A24: cabang S4 | B24: =VLOOKUP($B$7,'DATA PENGEUKURAN GARDU'!$H:$BV,42,0) -> 0
A25: cabang T4 | B25: =VLOOKUP($B$7,'DATA PENGEUKURAN GARDU'!$H:$BV,42,0) -> 0
A26: BEBAN TRAFO | B26: =VLOOKUP($B$7,'DATA PENGEUKURAN GARDU'!$H:$BV,65,0) -> Underload
A27: BEBAN SEIMBANG | B27: =VLOOKUP($B$7,'DATA PENGEUKURAN GARDU'!$H:$BV,66,0) -> TDK SEIMBANG
A28: DROP TEGANGAN | B28: =VLOOKUP($B$7,'DATA PENGEUKURAN GARDU'!$H:$BV,67,0) -> NORMAL
A29: KAPASITAS TRAFO | B29: =VLOOKUP($B$7,'DATA PENGEUKURAN GARDU'!$H:$BV,61,0) -> 6.9897767 | F29: % | G29: =IF(B29>70%,"OVERLOAD","TRAFO AMAN") -> OVERLOAD | H29: TEK | I29: MOYONGKOTA | J29: BOLAANG MONGONDOW TIMUR | K29: KMO 3 | L29: 0.73105902 | M29: 124.35713
A30: JADWAL PADAM | I30: MOYONGKOTA | J30: BOLAANG MONGONDOW TIMUR | K30: KMO 4 | L30: 0.72947103 | M30: 124.35571
A31: CEK BAGIAN ADMINISTRASI | I31: MOLOBOG | J31: BOLAANG MONGONDOW TIMUR | K31: KMO 49 | L31: 0.63827401 | M31: 124.52997
A32: ISIAN INFO AGENDA | I32: MOLOBOG | J32: BOLAANG MONGONDOW TIMUR | K32: KMO 53 | L32: 0.65332598 | M32: 124.54971
B33: DATA INTI | C33: DATA CADANGAN | F33: SATUAN | G33: KETERANGAN | H33: PIC | I33: JIKO | J33: BOLAANG MONGONDOW TIMUR | K33: KMO 56 | L33: 0.62147599 | M33: 124.54624
A34: POTENSI PIUTANG PRR / P2TL | B34: {=LOOKUP(1,1/FREQUENCY(0,MMULT(('DATA PRR'!$H:$I-$A$5:$B$5)^2,{1;1})),'DATA PRR'!G:G)} -> PRR 317000284000 SAHARJO MAMALO R1M 900 peta | C34: =IFERROR(VLOOKUP($C$5,'DATA PRR'!$D:$G,4,0),"") -> PRR 317000007561 IBRAHIM MIDU R1 1300 peta | F34: PLG | H34: NIAGA | I34: PALELON | J34: MINAHASA SELATAN | K34: KMO 133 | L34: 0.80663902 | M34: 124.43892
A35: ISIAN MANUAL/ SLO/RESTITUSI | B35: {=LOOKUP(1,1/FREQUENCY(0,MMULT(('DATA SLO'!$H:$I-$A$5:$B$5)^2,{1;1})),'DATA SLO'!G:G)} -> BLM TERBIT SLO 317000284000 SAHARJO MAMALO R1M 900 peta | C35: =IFERROR(VLOOKUP($C$5,'DATA SLO'!$D:$G,4,0),"") -> TERBIT SLO 317000007561 IBRAHIM MIDU R1 1300 peta | H35: NIAGA | I35: WULURMAATUS | J35: MINAHASA SELATAN | K35: KMO 138 | L35: 0.81015199 | M35: 124.43267
A36: JUMLAH HARI LAYANAN | B36: =VLOOKUP($C$5,'MONITORING HARI LAYANAN'!$E:$U,17,0) -> #N/A | C36: =VLOOKUP($D$5,'MONITORING HARI LAYANAN'!$A:$U,21,0) -> 2 | F36: HARI | H36: NIAGA | I36: MOKOBANG | J36: MINAHASA SELATAN | K36: KMO 140 | L36: 0.84362203 | M36: 124.43693
A37: STATUS PERMOHONAN/BAYAR/SURVEI/PKBA/ENTRI PDL/REMAJA | B37: =VLOOKUP($C$5,'MONITORING HARI LAYANAN'!$E:$AH,30,0) -> #N/A | C37: =VLOOKUP($D$5,'MONITORING HARI LAYANAN'!$A:$AH,34,0) -> PEREMAJAAN | H37: NIAGA | I37: MOTONGKAT | J37: BOLAANG MONGONDOW TIMUR | K37: KMO 157 | L37: 0.66319901 | M37: 124.55881
A38: MONITORING STOK MATERIAL ULP | I38: MODAYAG | J38: BOLAANG MONGONDOW TIMUR | K38: KMO 22 | L38: 0.710985 | M38: 124.38274
A39: NAMA MATERIAL | B39: SATUAN | C39: JENIS PLGAN | D39: STOK UP3 | E39: STOK ULP | F39: STOK PINJAM | G39: PIC | H39: KETERANGAN | I39: MODAYAG | J39: BOLAANG MONGONDOW TIMUR | K39: KMO 22 | L39: 0.710985 | M39: 124.38274
A40: MCB | B40: =G5 -> 1 FASA | C40: =IFERROR(VLOOKUP($F$5,'DATA MATERIAL TEL TEK'!$C:$H,4,0),"") -> 6A | D40: =IFERROR(VLOOKUP($C40,'DATA MATERIAL TEL TEK'!$F:$J,2,0),"") -> 21 | E40: =IFERROR(VLOOKUP($C40,'DATA MATERIAL TEL TEK'!$F:$J,3,0),"") -> 3 | F40: =IFERROR(VLOOKUP($C40,'DATA MATERIAL TEL TEK'!$F:$J,4,0),"") -> 8 | G40: =IFERROR(VLOOKUP($A40&B40,'DATA MATERIAL TEL TEK'!$B:$J,9,0),"") | I40: LIBERIA | J40: BOLAANG MONGONDOW TIMUR | K40: KMO 84 | L40: 0.719455 | M40: 124.3939
...

Sheet DATA PENGUKURAN GARDU
B1: PENGUKURAN GARDU DISTRIBUSI
B2: ULP IMANDI BULAN JANUARI 2024
B4: NO | C4: No, Gardu | D4: Penyulang | E4: Section | F4: Tipe Trafo | G4: Nama / Lokasi | H4: Merk Trafo | I4: Jenis Gardu | J4: Daya (kVA) | K4: Jlh Fasa | L4: Tegangan Nominal | N4: Arus Nominal | P4: Tgl & Jam Pengukuran | T4: Hasil Pengukuran Siang | AL4: Tgl & Jam Pengukuran | AO4: Hasil Pengukuran Malam | BG4: TAP | BH4: Status | BI4: Koordinat | BK4: Panjang JTR (KMS) | BL4: Keterangan | BM4: BEBAN PUNCAK | BN4: PEMBEBANAN | BP4: KESEIMBANGAN BEBAN | BR4: DROP TEGANGAN
T5: Nama Jurusan | AB5: Rata -Rata (A) | AC5: Beban | AE5: Keseimbangan Beban | AF5: Pangkal (V) | AH5: Ujung (V) | AI5: Overload Phasa | AO5: Nama Jurusan | AW5: Rata -Rata (A) | AX5: Beban | AZ5: Keseimbangan Beban | BA5: Pangkal (V) | BC5: Ujung (V) | BD5: Overload Phasa
L6: PRI (KV) | M6: SEK (V) | N6: PRI (A) | O6: SEK (A) | P6: Tgl | Q6: Bln | R6: Thn | U6: R | V6: % | W6: S | X6: % | Y6: T | Z6: % | AA6: N | AC6: kVA | AD6: % | AF6: L - N | AG6: L - L | AH6: L - N | AI6: R | AJ6: S | AK6: T | AL6: Tgl | AM6: Bln | AN6: Thn | AP6: R | AQ6: % | AR6: S | AS6: % | AT6: T | AU6: % | AV6: N | AX6: kVA | AY6: % | BA6: L - N | BB6: L - L | BC6: L - N | BD6: R | BE6: S | BF6: T | BI6: Latitude X | BJ6: Longitude Y | BN6: SIANG | BO6: MALAM | BP6: SIANG | BQ6: MALAM | BR6: SIANG | BS6: MALAM
A8: =C8&T8 -> Induk | B8: 1 | D8: SLO 7 | F8: Umum | G8: PERUM OM OKU | I8: PORTAL | J8: 50 | K8: 3 | L8: 20 | M8: =+IF(K8=3,400,IF(K8=1,230,0)) -> 400 | N8: =(J8*1000)/((L8*1000)*1.73) -> 1.4450867 | O8: =IF(K8=3,(J8*1000)/(M8*1.73),(J8*1000)/(M8)) -> 72.254335 | P8: 30 | Q8: JULI | R8: 2025 | T8: Induk | U8: =SUM(U9:U11) -> 0 | V8: =U8/O8*100 -> 0 | W8: =SUM(W9:W11) -> 0 | X8: =W8/O8*100 -> 0 | Y8: =SUM(Y9:Y11) -> 0 | Z8: =Y8/O8*100 -> 0 | AA8: =SUM(AA9:AA11) -> 0 | AB8: =IF((K8=3),(AVERAGE(U8,W8,Y8)),U8) -> 0 | AC8: =IFERROR(IF((K8=1),(AB8*AF8)/1000,(AB8*AG8*1.73)/1000),"0") -> 0 | AD8: =AC8/J8*100 -> 0 | AE8: =IF($K$8=1,"1 Phase",ABS(((U8/AB8)-1)+ABS((W8/AB8)-1)+ABS((Y8/AB8)-1))/3) -> #DIV/0! | AF8: 222 | AG8: 387 | AH8: 219.5 | AI8: =IF(U8>O8,"OL PHASA","Normal") -> Normal | AJ8: =IF(W8>O8,"OL PHASA","Normal") -> Normal | AK8: =IF(Y8>O8,"OL PHASA","Normal") -> Normal | AL8: 30 | AM8: JULI | AN8: 2025 | AO8: Induk | AP8: =SUM(AP9:AP11) -> 4 | AQ8: =AP8/O8*100 -> 5.536 | AR8: =SUM(AR9:AR11) -> 3 | AS8: =AR8/O8*100 -> 4.152 | AT8: =SUM(AT9:AT11) -> 5 | AU8: =AT8/O8*100 -> 6.92 | AV8: =SUM(AV9:AV11) -> 3 | AW8: =IF((K8=3),(AVERAGE(AP8,AR8,AT8)),AP8) -> 4 | AX8: =IFERROR(IF((K8=1),(AW8*BA8)/1000,(AW8*BB8*1.73)/1000),"0") -> 2.83028 | AY8: =AX8/J8*100 -> 5.66056 | AZ8: =IF($K$8=1,"1 Phase",ABS(((AP8/AW8)-1)+ABS((AR8/AW8)-1)+ABS((AT8/AW8)-1))/3) -> 0.16666667 | BA8: 238 | BB8: 409 | BD8: =IF(AP8>O8,"OL PHASA","Normal") -> Normal | BE8: =IF(AR8>O8,"OL PHASA","Normal") -> Normal | BF8: =IF(AT8>O8,"OL PHASA","Normal") -> Normal | BG8: - | BH8: Active | BI8: 0.54972 | BJ8: 123.93877 | BK8: 2164 | BL8: Sudah EAM | BM8: =IF(AY8>AD8,"Beban Malam","Beban Siang") -> Beban Malam | BN8: =IF(AD8<30,"Underload",IF(AD8<=80,"Baik",IF(AD8>80,"Overload"))) -> Underload | BO8: =IF(AY8<30,"Underload",IF(AY8<=80,"Baik",IF(AY8>80,"Overload"))) -> Underload | BP8: =IF(K8=3,IF(AE8>0.2,"TDK SEIMBANG","SEIMBANG"),IF(AI8="OL PHASA","TDK SEIMBANG","SEIMBANG")) -> #DIV/0! | BQ8: =IF(K8=3,IF(AZ8>0.2,"TDK SEIMBANG","SEIMBANG"),IF(BD8="OL PHASA","TDK SEIMBANG","SEIMBANG")) -> SEIMBANG | BR8: =IF(K8=3,IF(SUM(AF8:AG8)>600,"NORMAL","DROP"),IF(AH9>198,"NORMAL","DROP")) -> NORMAL | BS8: =IF(K8=3,IF(SUM(BA8:BB8)>600,"NORMAL","DROP"),IF(BC8>198,"NORMAL","DROP")) -> NORMAL
A9: =C9&T9 -> Jurusan 1 | D9: =IF(T9="","",D8) -> SLO 7 | T9: Jurusan 1 | AF9: 223 | AG9: 381 | AO9: Jurusan 1 | AP9: 4 | AR9: 3 | AT9: 5 | AV9: 3 | BA9: 236 | BB9: 413
A10: =C10&T10 -> Jurusan 2 | D10: =IF(T10="","",D9) -> SLO 7 | T10: Jurusan 2 | AF10: 220 | AG10: 384 | AO10: Jurusan 2 | BA10: 235 | BB10: 416
A11: =C11&T11 -> Jurusan 3 | D11: =IF(T11="","",D10) -> SLO 7 | T11: Jurusan 3 | AO11: Jurusan 3
A12: =C12&T12 | D12: =IF(T12="","",D11)
A13: =C13&T13 -> Induk | B13: =B8+1 -> 2 | D13: =IF(T13="","",D12) | F13: Umum | G13: PERUM GMP POYOWA BESAR | H13: KALTRA | I13: PORTAL | J13: 50 | K13: 3 | L13: 20 | M13: =+IF(K13=3,400,IF(K13=1,230,0)) -> 400 | N13: =(J13*1000)/((L13*1000)*1.73) -> 1.4450867 | O13: =IF(K13=3,(J13*1000)/(M13*1.73),(J13*1000)/(M13)) -> 72.254335 | P13: 30 | Q13: JULI | R13: 2025 | T13: Induk | U13: =SUM(U14:U16) -> 0 | V13: =U13/O13*100 -> 0 | W13: =SUM(W14:W16) -> 0 | X13: =W13/O13*100 -> 0 | Y13: =SUM(Y14:Y16) -> 0 | Z13: =Y13/O13*100 -> 0 | AA13: =SUM(AA14:AA16) -> 0 | AB13: =IF((K13=3),(AVERAGE(U13,W13,Y13)),U13) -> 0 | AC13: =IFERROR(IF((K13=1),(AB13*AF13)/1000,(AB13*AG13*1.73)/1000),"0") -> 0 | AD13: =AC13/J13*100 -> 0 | AE13: =IF($K$8=1,"1 Phase",ABS(((U13/AB13)-1)+ABS((W13/AB13)-1)+ABS((Y13/AB13)-1))/3) -> #DIV/0! | AF13: 225 | AG13: 395 | AI13: =IF(U13>O13,"OL PHASA","Normal") -> Normal | AJ13: =IF(W13>O13,"OL PHASA","Normal") -> Normal | AK13: =IF(Y13>O13,"OL PHASA","Normal") -> Normal | AL13: 30 | AM13: JULI | AN13: 2025 | AO13: Induk | AP13: =SUM(AP14:AP16) -> 3 | AQ13: =AP13/O13*100 -> 4.152 | AR13: =SUM(AR14:AR16) -> 0 | AS13: =AR13/O13*100 -> 0 | AT13: =SUM(AT14:AT16) -> 3 | AU13: =AT13/O13*100 -> 4.152 | AV13: =SUM(AV14:AV16) -> 3 | AW13: =IF((K13=3),(AVERAGE(AP13,AR13,AT13)),AP13) -> 2 | AX13: =IFERROR(IF((K13=1),(AW13*BA13)/1000,(AW13*BB13*1.73)/1000),"0") -> 1.41514 | AY13: =AX13/J13*100 -> 2.83028 | AZ13: =IF($K$8=1,"1 Phase",ABS(((AP13/AW13)-1)+ABS((AR13/AW13)-1)+ABS((AT13/AW13)-1))/3) -> 0.66666667 | BA13: 231 | BB13: 409 | BD13: =IF(AP13>O13,"OL PHASA","Normal") -> Normal | BE13: =IF(AR13>O13,"OL PHASA","Normal") -> Normal | BF13: =IF(AT13>O13,"OL PHASA","Normal") -> Normal | BG13: - | BH13: Active | BK13: 1080 | BL13: Sudah EAM | BM13: =IF(AY13>AD13,"Beban Malam","Beban Siang") -> Beban Malam | BN13: =IF(AD13<30,"Underload",IF(AD13<=80,"Baik",IF(AD13>80,"Overload"))) -> Underload | BO13: =IF(AY13<30,"Underload",IF(AY13<=80,"Baik",IF(AY13>80,"Overload"))) -> Underload | BP13: =IF(K13=3,IF(AE13>0.2,"TDK SEIMBANG","SEIMBANG"),IF(AI13="OL PHASA","TDK SEIMBANG","SEIMBANG")) -> #DIV/0! | BQ13: =IF(K13=3,IF(AZ13>0.2,"TDK SEIMBANG","SEIMBANG"),IF(BD13="OL PHASA","TDK SEIMBANG","SEIMBANG")) -> TDK SEIMBANG | BR13: =IF(K13=3,IF(SUM(AF13:AG13)>600,"NORMAL","DROP"),IF(AH14>198,"NORMAL","DROP")) -> NORMAL | BS13: =IF(K13=3,IF(SUM(BA13:BB13)>600,"NORMAL","DROP"),IF(BC13>198,"NORMAL","DROP")) -> NORMAL
A14: =C14&T14 -> Jurusan 1 | D14: =IF(T14="","",D13) | T14: Jurusan 1 | AF14: 230 | AG14: 390 | AH14: 225 | AO14: Jurusan 1 | AP14: 3 | AR14: 0 | AT14: 3 | AV14: 3 | BA14: 233 | BB14: 403
A15: =C15&T15 -> Jurusan 2 | D15: =IF(T15="","",D14) | T15: Jurusan 2 | AF15: 227 | AG15: 397 | AH15: 227 | AO15: Jurusan 2 | BA15: 230 | BB15: 406
A16: =C16&T16 -> Jurusan 3 | D16: =IF(T16="","",D15) | T16: Jurusan 3 | AO16: Jurusan 3
A17: =C17&T17 | D17: =IF(T17="","",D16)
A18: =C18&T18 -> K-143Induk | B18: =B13+1 -> 3 | C18: K-143 | D18: =IF(T18="","",D17) | G18: LAPANGAN NUNUK MATALI | H18: TRAFINDO | I18: PORTAL | J18: 160 | K18: 3 | L18: 20 | M18: =+IF(K18=3,400,IF(K18=1,230,0)) -> 400 | N18: =(J18*1000)/((L18*1000)*1.73) -> 4.6242775 | O18: =IF(K18=3,(J18*1000)/(M18*1.73),(J18*1000)/(M18)) -> 231.21387 | P18: 18 | Q18: JAN | R18: 2024 | T18: Induk | U18: =SUM(U19:U21) -> 77 | V18: =U18/O18*100 -> 33.3025 | W18: =SUM(W19:W21) -> 77 | X18: =W18/O18*100 -> 33.3025 | Y18: =SUM(Y19:Y21) -> 91 | Z18: =Y18/O18*100 -> 39.3575 | AA18: =SUM(AA19:AA21) -> 29 | AB18: =IF((K18=3),(AVERAGE(U18,W18,Y18)),U18) -> 81.666667 | AC18: =IFERROR(IF((K18=1),(AB18*AF18)/1000,(AB18*AG18*1.73)/1000),"0") -> 54.394083 | AD18: =AC18/J18*100 -> 33.996302 | AE18: =IF($K$8=1,"1 Phase",ABS(((U18/AB18)-1)+ABS((W18/AB18)-1)+ABS((Y18/AB18)-1))/3) -> 0.038095238 | AF18: 221 | AG18: 385 | AH18: 218 | AI18: =IF(U18>O18,"OL PHASA","Normal") -> Normal | AJ18: =IF(W18>O18,"OL PHASA","Normal") -> Normal | AK18: =IF(Y18>O18,"OL PHASA","Normal") -> Normal | AL18: 17 | AM18: JAN | AN18: 2024 | AO18: Induk | AP18: =SUM(AP19:AP21) -> 77 | AQ18: =AP18/O18*100 -> 33.3025 | AR18: =SUM(AR19:AR21) -> 77 | AS18: =AR18/O18*100 -> 33.3025 | AT18: =SUM(AT19:AT21) -> 91 | AU18: =AT18/O18*100 -> 39.3575 | AV18: =SUM(AV19:AV21) -> 29 | AW18: =IF((K18=3),(AVERAGE(AP18,AR18,AT18)),AP18) -> 81.666667 | AX18: =IFERROR(IF((K18=1),(AW18*BA18)/1000,(AW18*BB18*1.73)/1000),"0") -> 54.959217 | AY18: =AX18/J18*100 -> 34.34951 | AZ18: =IF($K$8=1,"1 Phase",ABS(((AP18/AW18)-1)+ABS((AR18/AW18)-1)+ABS((AT18/AW18)-1))/3) -> 0.038095238 | BA18: 223 | BB18: 389 | BC18: 218 | BD18: =IF(AP18>O18,"OL PHASA","Normal") -> Normal | BE18: =IF(AR18>O18,"OL PHASA","Normal") -> Normal | BF18: =IF(AT18>O18,"OL PHASA","Normal") -> Normal | BG18: - | BH18: Active | BK18: 2100 | BL18: Sudah EAM | BM18: =IF(AY18>AD18,"Beban Malam","Beban Siang") -> Beban Malam | BN18: =IF(AD18<30,"Underload",IF(AD18<=80,"Baik",IF(AD18>80,"Overload"))) -> Baik | BO18: =IF(AY18<30,"Underload",IF(AY18<=80,"Baik",IF(AY18>80,"Overload"))) -> Baik | BP18: =IF(K18=3,IF(AE18>0.2,"TDK SEIMBANG","SEIMBANG"),IF(AI18="OL PHASA","TDK SEIMBANG","SEIMBANG")) -> SEIMBANG | BQ18: =IF(K18=3,IF(AZ18>0.2,"TDK SEIMBANG","SEIMBANG"),IF(BD18="OL PHASA","TDK SEIMBANG","SEIMBANG")) -> SEIMBANG | BR18: =IF(K18=3,IF(SUM(AF18:AG18)>600,"NORMAL","DROP"),IF(AH19>198,"NORMAL","DROP")) -> NORMAL | BS18: =IF(K18=3,IF(SUM(BA18:BB18)>600,"NORMAL","DROP"),IF(BC19>198,"NORMAL","DROP")) -> NORMAL
A19: =C19&T19 -> K-143Jurusan 1 | C19: =IF(T19="","",C18) -> K-143 | D19: =IF(T19="","",D18) | T19: Jurusan 1 | U19: 50 | W19: 60 | Y19: 65 | AA19: 18 | AF19: 221 | AG19: 381 | AO19: Jurusan 1 | AP19: 50 | AR19: 60 | AT19: 65 | AV19: 18 | BA19: 224 | BB19: 384
A20: =C20&T20 -> K-143Jurusan 2 | C20: =IF(T20="","",C19) -> K-143 | D20: =IF(T20="","",D19) | T20: Jurusan 2 | U20: 27 | W20: 17 | Y20: 26 | AA20: 11 | AF20: 219 | AG20: 381 | AO20: Jurusan 2 | AP20: 27 | AR20: 17 | AT20: 26 | AV20: 11 | BA20: 221 | BB20: 386
A21: =C21&T21 -> K-143Jurusan 3 | C21: =IF(T21="","",C20) -> K-143 | D21: =IF(T21="","",D20) | T21: Jurusan 3 | AO21: Jurusan 3
A22: =C22&T22 | C22: =IF(T22="","",C21) | D22: =IF(T22="","",D21)
A23: =C23&T23 -> K-141Induk | B23: =B18+1 -> 4 | C23: K-141 | D23: =IF(T23="","",D22) | F23: Khusus | G23: PERUM GRYIA POBUNDAYAN | H23: KALTRA | I23: PORTAL | J23: 100 | K23: 3 | L23: 20 | M23: =+IF(K23=3,400,IF(K23=1,230,0)) -> 400 | N23: =(J23*1000)/((L23*1000)*1.73) -> 2.8901734 | O23: =IF(K23=3,(J23*1000)/(M23*1.73),(J23*1000)/(M23)) -> 144.50867 | P23: 29 | Q23: JAN | R23: 2025 | T23: Induk | U23: =SUM(U24:U26) -> 62 | V23: =U23/O23*100 -> 42.904 | W23: =SUM(W24:W26) -> 95 | X23: =W23/O23*100 -> 65.74 | Y23: =SUM(Y24:Y26) -> 73 | Z23: =Y23/O23*100 -> 50.516 | AA23: =SUM(AA24:AA26) -> 57 | AB23: =IF((K23=3),(AVERAGE(U23,W23,Y23)),U23) -> 76.666667 | AC23: =IFERROR(IF((K23=1),(AB23*AF23)/1000,(AB23*AG23*1.73)/1000),"0") -> 55.573367 | AD23: =AC23/J23*100 -> 55.573367 | AE23: =IF($K$8=1,"1 Phase",ABS(((U23/AB23)-1)+ABS((W23/AB23)-1)+ABS((Y23/AB23)-1))/3) -> 0.031884058 | AF23: 238 | AG23: 419 | AI23: =IF(U23>O23,"OL PHASA","Normal") -> Normal | AJ23: =IF(W23>O23,"OL PHASA","Normal") -> Normal | AK23: =IF(Y23>O23,"OL PHASA","Normal") -> Normal | AL23: 23 | AM23: JAN | AN23: 2023 | AO23: Induk | AP23: 49 | AQ23: =AP23/O23*100 -> 33.908 | AR23: 17 | AS23: =AR23/O23*100 -> 11.764 | AT23: 78 | AU23: =AT23/O23*100 -> 53.976 | AV23: 60 | AW23: =IF((K23=3),(AVERAGE(AP23,AR23,AT23)),AP23) -> 48 | AX23: =IFERROR(IF((K23=1),(AW23*BA23)/1000,(AW23*BB23*1.73)/1000),"0") -> 34.21248 | AY23: =AX23/J23*100 -> 34.21248 | AZ23: =IF($K$8=1,"1 Phase",ABS(((AP23/AW23)-1)+ABS((AR23/AW23)-1)+ABS((AT23/AW23)-1))/3) -> 0.43055556 | BA23: 231 | BB23: 412 | BD23: =IF(AP23>O23,"OL PHASA","Normal") -> Normal | BE23: =IF(AR23>O23,"OL PHASA","Normal") -> Normal | BF23: =IF(AT23>O23,"OL PHASA","Normal") -> Normal | BG23: - | BH23: Active | BK23: 900 | BL23: Sudah EAM | BM23: =IF(AY23>AD23,"Beban Malam","Beban Siang") -> Beban Siang | BN23: =IF(AD23<30,"Underload",IF(AD23<=80,"Baik",IF(AD23>80,"Overload"))) -> Baik | BO23: =IF(AY23<30,"Underload",IF(AY23<=80,"Baik",IF(AY23>80,"Overload"))) -> Baik | BP23: =IF(K23=3,IF(AE23>0.2,"TDK SEIMBANG","SEIMBANG"),IF(AI23="OL PHASA","TDK SEIMBANG","SEIMBANG")) -> SEIMBANG | BQ23: =IF(K23=3,IF(AZ23>0.2,"TDK SEIMBANG","SEIMBANG"),IF(BD23="OL PHASA","TDK SEIMBANG","SEIMBANG")) -> TDK SEIMBANG | BR23: =IF(K23=3,IF(SUM(AF23:AG23)>600,"NORMAL","DROP"),IF(AH24>198,"NORMAL","DROP")) -> NORMAL | BS23: =IF(K23=3,IF(SUM(BA23:BB23)>600,"NORMAL","DROP"),IF(BC24>198,"NORMAL","DROP")) -> NORMAL
A24: =C24&T24 -> K-141Jurusan 1 | C24: =IF(T24="","",C23) -> K-141 | D24: =IF(T24="","",D23) | T24: Jurusan 1 | U24: 62 | W24: 69 | Y24: 59 | AA24: 35 | AF24: 244 | AG24: 410 | AH24: 224 | AO24: Jurusan 1 | AP24: 24 | AR24: 11 | AT24: 6 | AV24: 19 | BA24: 241 | BB24: 397 | BC24: 232
A25: =C25&T25 -> K-141Jurusan 2 | C25: =IF(T25="","",C24) -> K-141 | D25: =IF(T25="","",D24) | T25: Jurusan 2 | U25: 0 | W25: 26 | Y25: 14 | AA25: 22 | AF25: 238 | AG25: 418 | AH25: 219 | AO25: Jurusan 2 | AP25: 21 | AR25: 6 | AT25: 73 | AV25: 56 | BA25: 232 | BB25: 413.7
A26: =C26&T26 -> K-141Jurusan 3 | C26: =IF(T26="","",C25) -> K-141 | T26: Jurusan 3 | AO26: Jurusan 3
A27: =C27&T27 | C27: =IF(T27="","",C26)
A28: =C28&T28 -> K-072Induk | B28: =B23+1 -> 5 | C28: K-072 | F28: Umum | G28: BOHUSAMI TOWER | J28: 50 | K28: 3 | L28: 20 | M28: =+IF(K28=3,400,IF(K28=1,230,0)) -> 400 | N28: =(J28*1000)/((L28*1000)*1.73) -> 1.4450867 | O28: =IF(K28=3,(J28*1000)/(M28*1.73),(J28*1000)/(M28)) -> 72.254335 | P28: 23 | Q28: 4 | R28: 2025 | T28: Induk | U28: =SUM(U29:U31) -> 10 | V28: =U28/O28*100 -> 13.84 | W28: =SUM(W29:W31) -> 48 | X28: =W28/O28*100 -> 66.432 | Y28: =SUM(Y29:Y31) -> 18 | Z28: =Y28/O28*100 -> 24.912 | AA28: =SUM(AA29:AA31) -> 75 | AB28: =IF((K28=3),(AVERAGE(U28,W28,Y28)),U28) -> 25.333333 | AC28: =IFERROR(IF((K28=1),(AB28*AF28)/1000,(AB28*AG28*1.73)/1000),"0") -> 17.701591 | AD28: =AC28/J28*100 -> 35.403181 | AE28: =IF($K$8=1,"1 Phase",ABS(((U28/AB28)-1)+ABS((W28/AB28)-1)+ABS((Y28/AB28)-1))/3) -> 0.19298246 | AF28: 232 | AG28: 403.9 | AI28: =IF(U28>O28,"OL PHASA","Normal") -> Normal | AJ28: =IF(W28>O28,"OL PHASA","Normal") -> Normal | AK28: =IF(Y28>O28,"OL PHASA","Normal") -> Normal | AL28: 14 | AM28: JAN | AN28: 2024 | AO28: Induk | AP28: 44 | AQ28: 87.4 | AR28: 51 | AS28: =AR28/O28*100 -> 70.584 | AT28: 52 | AU28: =AT28/O28*100 -> 71.968 | AV28: 27 | AW28: =IF((K28=3),(AVERAGE(AP28,AR28,AT28)),AP28) -> 49 | AX28: =IFERROR(IF((K28=1),(AW28*BA28)/1000,(AW28*BB28*1.73)/1000),"0") -> 34.730269 | AY28: =AX28/J28*100 -> 69.460538 | AZ28: =IF($K$8=1,"1 Phase",ABS(((AP28/AW28)-1)+ABS((AR28/AW28)-1)+ABS((AT28/AW28)-1))/3) -> 3.7007434e-17 | BA28: 235 | BB28: 409.7 | BD28: =IF(AP28>O28,"OL PHASA","Normal") -> Normal | BE28: =IF(AR28>O28,"OL PHASA","Normal") -> Normal | BF28: =IF(AT28>O28,"OL PHASA","Normal") -> Normal | BG28: - | BH28: Active | BK28: 1350 | BL28: Sudah EAM | BM28: =IF(AY28>AD28,"Beban Malam","Beban Siang") -> Beban Malam | BN28: =IF(AD28<30,"Underload",IF(AD28<=80,"Baik",IF(AD28>80,"Overload"))) -> Baik | BO28: =IF(AY28<30,"Underload",IF(AY28<=80,"Baik",IF(AY28>80,"Overload"))) -> Baik | BP28: =IF(K28=3,IF(AE28>0.2,"TDK SEIMBANG","SEIMBANG"),IF(AI28="OL PHASA","TDK SEIMBANG","SEIMBANG")) -> SEIMBANG | BQ28: =IF(K28=3,IF(AZ28>0.2,"TDK SEIMBANG","SEIMBANG"),IF(BD28="OL PHASA","TDK SEIMBANG","SEIMBANG")) -> SEIMBANG | BR28: =IF(K28=3,IF(SUM(AF28:AG28)>600,"NORMAL","DROP"),IF(AH29>198,"NORMAL","DROP")) -> NORMAL | BS28: =IF(K28=3,IF(SUM(BA28:BB28)>600,"NORMAL","DROP"),IF(BC29>198,"NORMAL","DROP")) -> NORMAL
A29: =C29&T29 -> K-072Jurusan 1 | C29: =IF(T29="","",C28) -> K-072 | T29: Jurusan 1 | U29: 10 | W29: 9 | Y29: 18 | AA29: 36 | AF29: 233 | AG29: 401 | AH29: 221 | AO29: Jurusan 1 | AP29: 40 | AR29: 49 | AT29: 41 | AV29: 24 | BA29: 236 | BB29: 399.7 | BC29: 233
A30: =C30&T30 -> K-072Jurusan 2 | C30: =IF(T30="","",C29) -> K-072 | T30: Jurusan 2 | U30: 0 | W30: 39 | Y30: 0 | AA30: 39 | AF30: 232 | AG30: 403 | AH30: 233 | AO30: Jurusan 2 | AP30: 5.5 | AR30: 4 | AT30: 11 | AV30: 1.8 | BA30: 234 | BB30: 404.8 | BC30: 235
A31: =C31&T31 -> K-072Jurusan 3 | C31: =IF(T31="","",C30) -> K-072 | T31: Jurusan 3 | AO31: Jurusan 3
A32: =C32&T32 | C32: =IF(T32="","",C31)
A33: =C33&T33 -> K-138,1Induk | B33: =B28+1 -> 6 | C33: K-138,1 | F33: Umum | I33: PORTAL | J33: 160 | K33: 3 | L33: 20 | M33: =+IF(K33=3,400,IF(K33=1,230,0)) -> 400 | N33: =(J33*1000)/((L33*1000)*1.73) -> 4.6242775 | O33: =IF(K33=3,(J33*1000)/(M33*1.73),(J33*1000)/(M33)) -> 231.21387 | T33: Induk | U33: =SUM(U34:U36) -> 100 | V33: =U33/O33*100 -> 43.25 | W33: =SUM(W34:W36) -> 121 | X33: =W33/O33*100 -> 52.3325 | Y33: =SUM(Y34:Y36) -> 139 | Z33: =Y33/O33*100 -> 60.1175 | AA33: =SUM(AA34:AA36) -> 64 | AB33: =IF((K33=3),(AVERAGE(U33,W33,Y33)),U33) -> 120 | AC33: =IFERROR(IF((K33=1),(AB33*AF33)/1000,(AB33*AG33*1.73)/1000),"0") -> 83.2476 | AD33: =AC33/J33*100 -> 52.02975 | AE33: =IF($K$8=1,"1 Phase",ABS(((U33/AB33)-1)+ABS((W33/AB33)-1)+ABS((Y33/AB33)-1))/3) -> 0 | AF33: 231 | AG33: 401 | AH33: 225 | AI33: =IF(U33>O33,"OL PHASA","Normal") -> Normal | AJ33: =IF(W33>O33,"OL PHASA","Normal") -> Normal | AK33: =IF(Y33>O33,"OL PHASA","Normal") -> Normal | AL33: 14 | AM33: JAN | AN33: 2024 | AO33: Induk | AP33: 52 | AQ33: =AP33/O33*100 -> 22.49 | AR33: 0 | AS33: =AR33/O33*100 -> 0 | AT33: 0 | AU33: =AT33/O33*100 -> 0 | AV33: 53 | AW33: =IF((K33=3),(AVERAGE(AP33,AR33,AT33)),AP33) -> 17.333333 | AX33: =IFERROR(IF((K33=1),(AW33*BA33)/1000,(AW33*BB33*1.73)/1000),"0") -> 0 | AY33: =AX33/J33*100 -> 0 | AZ33: =IF($K$8=1,"1 Phase",ABS(((AP33/AW33)-1)+ABS((AR33/AW33)-1)+ABS((AT33/AW33)-1))/3) -> 1.3333333 | BA33: 212 | BB33: 0 | BC33: 206 | BD33: =IF(AP33>O33,"OL PHASA","Normal") -> Normal | BE33: =IF(AR33>O33,"OL PHASA","Normal") -> Normal | BF33: =IF(AT33>O33,"OL PHASA","Normal") -> Normal | BG33: - | BH33: Active | BK33: 495 | BL33: Sudah EAM | BM33: =IF(AY33>AD33,"Beban Malam","Beban Siang") -> Beban Siang | BN33: =IF(AD33<30,"Underload",IF(AD33<=80,"Baik",IF(AD33>80,"Overload"))) -> Baik | BO33: =IF(AY33<30,"Underload",IF(AY33<=80,"Baik",IF(AY33>80,"Overload"))) -> Underload | BP33: =IF(K33=3,IF(AE33>0.2,"TDK SEIMBANG","SEIMBANG"),IF(AI33="OL PHASA","TDK SEIMBANG","SEIMBANG")) -> SEIMBANG | BQ33: =IF(K33=3,IF(AZ33>0.2,"TDK SEIMBANG","SEIMBANG"),IF(BD33="OL PHASA","TDK SEIMBANG","SEIMBANG")) -> TDK SEIMBANG | BR33: =IF(K33=3,IF(SUM(AF33:AG33)>600,"NORMAL","DROP"),IF(AH34>198,"NORMAL","DROP")) -> NORMAL | BS33: =IF(K33=3,IF(SUM(BA33:BB33)>600,"NORMAL","DROP"),IF(BC34>198,"NORMAL","DROP")) -> DROP
A34: =C34&T34 -> K-138,1Jurusan 1 | C34: =IF(T34="","",C33) -> K-138,1 | T34: Jurusan 1 | U34: 72 | W34: 106 | Y34: 112 | AA34: 45 | AO34: Jurusan 1
A35: =C35&T35 -> K-138,1Jurusan 2 | C35: =IF(T35="","",C34) -> K-138,1 | T35: Jurusan 2 | U35: 28 | W35: 15 | Y35: 27 | AA35: 19 | AO35: Jurusan 2
A36: =C36&T36 -> K-138,1Jurusan 3 | C36: =IF(T36="","",C35) -> K-138,1 | T36: Jurusan 3 | AO36: Jurusan 3
A37: =C37&T37 | C37: =IF(T37="","",C36)
A38: =C38&T38 -> K-038Induk | B38: =B33+1 -> 7 | C38: K-038 | G38: LOBONG | H38: SINTRA | I38: PORTAL | J38: 100 | K38: 3 | L38: 20 | M38: =+IF(K38=3,400,IF(K38=1,230,0)) -> 400 | N38: =(J38*1000)/((L38*1000)*1.73) -> 2.8901734 | O38: =IF(K38=3,(J38*1000)/(M38*1.73),(J38*1000)/(M38)) -> 144.50867 | P38: 17 | Q38: JAN | R38: 2024 | T38: Induk | U38: =SUM(U39:U41) -> 117 | V38: =U38/O38*100 -> 80.964 | W38: =SUM(W39:W41) -> 112 | X38: =W38/O38*100 -> 77.504 | Y38: =SUM(Y39:Y41) -> 113 | Z38: =Y38/O38*100 -> 78.196 | AA38: =SUM(AA39:AA41) -> 51 | AB38: =IF((K38=3),(AVERAGE(U38,W38,Y38)),U38) -> 114 | AC38: =IFERROR(IF((K38=1),(AB38*AF38)/1000,(AB38*AG38*1.73)/1000),"0") -> 75.9297 | AD38: =AC38/J38*100 -> 75.9297 | AE38: =IF($K$8=1,"1 Phase",ABS(((U38/AB38)-1)+ABS((W38/AB38)-1)+ABS((Y38/AB38)-1))/3) -> 0.01754386 | AF38: 222 | AG38: 385 | AI38: =IF(U38>O38,"OL PHASA","Normal") -> Normal | AJ38: =IF(W38>O38,"OL PHASA","Normal") -> Normal | AK38: =IF(Y38>O38,"OL PHASA","Normal") -> Normal | AL38: 14 | AM38: JAN | AN38: 2024 | AO38: Induk | AP38: 22 | AQ38: =AP38/O38*100 -> 15.224 | AR38: 15 | AS38: =AR38/O38*100 -> 10.38 | AT38: 15 | AU38: =AT38/O38*100 -> 10.38 | AV38: 14 | AW38: =IF((K38=3),(AVERAGE(AP38,AR38,AT38)),AP38) -> 17.333333 | AX38: =IFERROR(IF((K38=1),(AW38*BA38)/1000,(AW38*BB38*1.73)/1000),"0") -> 11.78476 | AY38: =AX38/J38*100 -> 11.78476 | AZ38: =IF($K$8=1,"1 Phase",ABS(((AP38/AW38)-1)+ABS((AR38/AW38)-1)+ABS((AT38/AW38)-1))/3) -> 0.17948718 | BA38: 227 | BB38: 393 | BD38: =IF(AP38>O38,"OL PHASA","Normal") -> Normal | BE38: =IF(AR38>O38,"OL PHASA","Normal") -> Normal | BF38: =IF(AT38>O38,"OL PHASA","Normal") -> Normal | BG38: 4 | BH38: Active | BK38: 810 | BL38: Sudah EAM | BM38: =IF(AY38>AD38,"Beban Malam","Beban Siang") -> Beban Siang | BN38: =IF(AD38<30,"Underload",IF(AD38<=80,"Baik",IF(AD38>80,"Overload"))) -> Baik | BO38: =IF(AY38<30,"Underload",IF(AY38<=80,"Baik",IF(AY38>80,"Overload"))) -> Underload | BP38: =IF(K38=3,IF(AE38>0.2,"TDK SEIMBANG","SEIMBANG"),IF(AI38="OL PHASA","TDK SEIMBANG","SEIMBANG")) -> SEIMBANG | BQ38: =IF(K38=3,IF(AZ38>0.2,"TDK SEIMBANG","SEIMBANG"),IF(BD38="OL PHASA","TDK SEIMBANG","SEIMBANG")) -> SEIMBANG | BR38: =IF(K38=3,IF(SUM(AF38:AG38)>600,"NORMAL","DROP"),IF(AH39>198,"NORMAL","DROP")) -> NORMAL | BS38: =IF(K38=3,IF(SUM(BA38:BB38)>600,"NORMAL","DROP"),IF(BC39>198,"NORMAL","DROP")) -> NORMAL
A39: =C39&T39 -> K-038Jurusan 1 | C39: =IF(T39="","",C38) -> K-038 | T39: Jurusan 1 | U39: =101+16 -> 117 | W39: =96+16 -> 112 | Y39: =97+16 -> 113 | AA39: =43+8 -> 51 | AF39: 222 | AG39: 384 | AH39: 219 | AO39: Jurusan 1 | AP39: 6 | AR39: 5 | AT39: 7 | AV39: 6 | BA39: 226 | BB39: 391.7 | BC39: 223
A40: =C40&T40 -> K-038Jurusan 2 | C40: =IF(T40="","",C39) -> K-038 | T40: Jurusan 2 | AF40: 221 | AG40: 383 | AH40: 219 | AO40: Jurusan 2 | AP40: 16 | AR40: 10 | AT40: 7 | AV40: 10 | BA40: 225 | BB40: 390 | BC40: 215
A41: =C41&T41 -> K-038Jurusan 3 | C41: =IF(T41="","",C40) -> K-038 | T41: Jurusan 3 | AO41: Jurusan 3
A42: =C42&T42 | C42: =IF(T42="","",C41)
...

Sheet DATA PENGEUKURAN GARDU
K1: Daya (kVA) | L1: Jlh Fasa | M1: Tegangan Nominal | O1: Arus Nominal | Q1: INDUK | AA1: JURUSAN 1 | AJ1: JURUSAN 2 | AS1: JURUSAN 3 | BB1: JURUSAN 4 | BK1: OVERLOAD PHASA | BT1: PEMBEBANAN | BU1: KESEIMBANGAN BEBAN | BV1: DROP TEGANGAN
F2: LOKASI | G2: ALAMAT | H2: KODE GARDU | I2: X | J2: Y | M2: PRI (KV) | N2: SEK (V) | O2: PRI (A) | P2: SEK (A) | Q2: ARUS R | R2: % | S2: ARUS S | T2: % | U2: ARUS T | V2: % | W2: ARUS N | X2: TEG PANGKAL (L-N) | Y2: TEG PANGKAL (L-L) | Z2: TEG UJUNG (L-N) | AA2: ARUS R | AB2: % | AC2: ARUS S | AD2: % | AE2: ARUS T | AF2: % | AG2: ARUS N | AH2: TEG PANGKAL (L-N) | AI2: TEG UJUNG (L-L) | AJ2: ARUS R | AK2: % | AL2: ARUS S | AM2: % | AN2: ARUS T | AO2: % | AP2: ARUS N | AQ2: TEG PANGKAL (L-N) | AR2: TEG UJUNG (L-N) | AS2: ARUS R | AT2: % | AU2: ARUS S | AV2: % | AW2: ARUS T | AX2: % | AY2: ARUS N | AZ2: TEG PANGKAL (L-N) | BA2: TEG UJUNG (L-N) | BB2: ARUS R | BC2: % | BD2: ARUS S | BE2: % | BF2: ARUS T | BG2: % | BH2: ARUS N | BI2: TEG PANGKAL (L-N) | BJ2: TEG UJUNG (L-N) | BK2: R | BL2: S | BM2: T | BN2: RATA2 ARUS | BO2: BEBAN KVA | BP2: BEBAN TRAFO % | BQ2: KEIMBANGAN BEBAN | BR2: PANJANG JTR KMS | BS2: TANGGAL & JAM UKUR | BT2: MALAM | BU2: MALAM | BV2: MALAM
A3: =H3&"Induk" -> BB 143.1Induk | B3: =H3&"jurusan 1" -> BB 143.1jurusan 1 | C3: =H3&"jurusan 2" -> BB 143.1jurusan 2 | D3: =H3&"jurusan 3" -> BB 143.1jurusan 3 | E3: =H3&"jurusan 4" -> BB 143.1jurusan 4 | F3: BIGO SELATAN | G3: BOLAANG MONGONDOW UTARA | H3: BB 143.1 | I3: 0.89482 | J3: 123.26336 | N3: =+IF(L3=3,400,IF(L3=1,230,0)) -> 0 | O3: =(K3*1000)/((M3*1000)*1.73) -> #VALUE! | P3: =IF(L3=3,(K3*1000)/(N3*1.73),(K3*1000)/(N3)) -> #VALUE! | Q3: =VLOOKUP($A3,'DATA PENGUKURAN GARDU'!$A:$BS,42,0) -> #N/A | R3: =Q3/$P3*100 -> #N/A | S3: =VLOOKUP($A3,'DATA PENGUKURAN GARDU'!$A:$BS,44,0) -> #N/A | T3: =S3/$P3*100 -> #N/A | U3: =VLOOKUP($A3,'DATA PENGUKURAN GARDU'!$A:$BS,46,0) -> #N/A | V3: =U3/$P3*100 -> #N/A | W3: =VLOOKUP($A3,'DATA PENGUKURAN GARDU'!$A:$BS,48,0) -> #N/A | X3: =VLOOKUP($A3,'DATA PENGUKURAN GARDU'!$A:$BS,53,0) -> #N/A | Y3: =VLOOKUP($A3,'DATA PENGUKURAN GARDU'!$A:$BS,54,0) -> #N/A | Z3: =VLOOKUP($A3,'DATA PENGUKURAN GARDU'!$A:$BS,55,0) -> #N/A | AA3: =VLOOKUP($B3,'DATA PENGUKURAN GARDU'!$A:$BS,42,0) -> #N/A | AB3: =AA3/$P3*100 -> #N/A | AC3: =VLOOKUP($B3,'DATA PENGUKURAN GARDU'!$A:$BS,44,0) -> #N/A | AD3: =AC3/$P3*100 -> #N/A | AE3: =VLOOKUP($B3,'DATA PENGUKURAN GARDU'!$A:$BS,46,0) -> #N/A | AF3: =AE3/$P3*100 -> #N/A | AG3: =VLOOKUP($B3,'DATA PENGUKURAN GARDU'!$A:$BS,46,0) -> #N/A | AH3: =VLOOKUP($B3,'DATA PENGUKURAN GARDU'!$A:$BS,53,0) -> #N/A | AI3: =VLOOKUP($B3,'DATA PENGUKURAN GARDU'!$A:$BS,54,0) -> #N/A | AJ3: =VLOOKUP($C3,'DATA PENGUKURAN GARDU'!$A:$BS,42,0) -> #N/A | AK3: =AJ3/$P3*100 -> #N/A | AL3: =VLOOKUP($C3,'DATA PENGUKURAN GARDU'!$A:$BS,44,0) -> #N/A | AM3: =AL3/$P3*100 -> #N/A | AN3: =VLOOKUP($C3,'DATA PENGUKURAN GARDU'!$A:$BS,46,0) -> #N/A | AO3: =AN3/$P3*100 -> #N/A | AP3: =VLOOKUP($C3,'DATA PENGUKURAN GARDU'!$A:$BS,46,0) -> #N/A | AQ3: =VLOOKUP($C3,'DATA PENGUKURAN GARDU'!$A:$BS,53,0) -> #N/A | AR3: =VLOOKUP($C3,'DATA PENGUKURAN GARDU'!$A:$BS,54,0) -> #N/A | AS3: =VLOOKUP($D3,'DATA PENGUKURAN GARDU'!$A:$BS,42,0) -> #N/A | AT3: =AS3/$P3*100 -> #N/A | AU3: =VLOOKUP($D3,'DATA PENGUKURAN GARDU'!$A:$BS,44,0) -> #N/A | AV3: =AU3/$P3*100 -> #N/A | AW3: =VLOOKUP($D3,'DATA PENGUKURAN GARDU'!$A:$BS,46,0) -> #N/A | AX3: =AW3/$P3*100 -> #N/A | AY3: =VLOOKUP($D3,'DATA PENGUKURAN GARDU'!$A:$BS,46,0) -> #N/A | AZ3: =VLOOKUP($D3,'DATA PENGUKURAN GARDU'!$A:$BS,53,0) -> #N/A | BA3: =VLOOKUP($D3,'DATA PENGUKURAN GARDU'!$A:$BS,54,0) -> #N/A | BB3: =VLOOKUP($E3,'DATA PENGUKURAN GARDU'!$A:$BS,42,0) -> #N/A | BC3: =BB3/$P3*100 -> #N/A | BD3: =VLOOKUP($E3,'DATA PENGUKURAN GARDU'!$A:$BS,44,0) -> #N/A | BE3: =BD3/$P3*100 -> #N/A | BF3: =VLOOKUP($E3,'DATA PENGUKURAN GARDU'!$A:$BS,46,0) -> #N/A | BG3: =BF3/$P3*100 -> #N/A | BH3: =VLOOKUP($E3,'DATA PENGUKURAN GARDU'!$A:$BS,46,0) -> #N/A | BI3: =VLOOKUP($E3,'DATA PENGUKURAN GARDU'!$A:$BS,53,0) -> #N/A | BJ3: =VLOOKUP($E3,'DATA PENGUKURAN GARDU'!$A:$BS,54,0) -> #N/A | BK3: =IF(Q3>P3,"OL PHASA","Normal") -> #N/A | BL3: =IF(S3>P3,"OL PHASA","Normal") -> #N/A | BM3: =IF(U3>P3,"OL PHASA","Normal") -> #N/A | BN3: =IF((L3=3),(AVERAGE(Q3,S3,U3)),MAX(Q3,S3,U3)) -> #N/A | BO3: =IFERROR(IF((L3=1),(BN3*AH3)/1000,(BN3*AI3*1.73)/1000),"0") -> 0 | BP3: =BO3/K3*100 -> #VALUE! | BQ3: =IF($L3=1,"1 Phase",ABS(((Q3/BN3)-1)+ABS((S3/BN3)-1)+ABS((U3/BN3)-1))/3) -> #N/A | BR3: #N/A | BS3: #N/A | BT3: =IF(BP3<30,"Underload",IF(BP3<=80,"Baik",IF(BP3>80,"Overload"))) -> #VALUE! | BU3: =IF(L3=3,IF(BQ3>0.2,"TDK SEIMBANG","SEIMBANG"),IF(BM3="OL PHASA","TDK SEIMBANG","SEIMBANG")) -> #N/A | BV3: =IF(L3=3,IF(SUM(X3:Y3)>600,"NORMAL","DROP"),IF(BD8>198,"NORMAL","DROP")) -> #N/A
